<?xml version="1.0"?>

<robot name="visual">


  <link name="base_link">
  <origin xyz="100 0 0 " rpy=" 0 0 0"/>
    <visual>
      <geometry>
         <cylinder length="0.01" radius="0.01"/>
      </geometry>
      <material name="yellow">
         <color rgba="1 1 0 1"/>
      </material>
    </visual>
  </link>

  <joint name="BaseToBottom" type="fixed">
    <origin xyz="0 0 0" rpy=" -1.57 3.14 0"/>
    <parent link="base_link"/>
    <child link="bottom"/>
    <limit effort="1.0" lower="0" upper="6" velocity="1.0"/>
    <axis xyz = "0 1 0"/>
  </joint>

  <link name="bottom">
  <origin xyz="0 0 0 " rpy=" 0 0 0"/>
    <visual>
      <geometry>
      <mesh filename="package://arm_3001/meshes/BaseAssy.stl" scale="0.05 0.05 0.05"/>
      </geometry>
      <material name="blue"/>
    </visual>
  </link>

  <joint name="Bottomtolink0" type="revolute">
    <origin xyz="0 10 0" rpy="0 3.14 0"/>
    <parent link="bottom"/>
    <child link="link0"/>
    <limit effort="1.0" lower="-2" upper="2" velocity="1.0"/>
    <axis xyz = "0 1 0"/>
  </joint>

  <link name="link0">
  <origin xyz="0 0 0 " rpy=" 0 0 0"/>
    <visual>
      <geometry>
      <mesh filename="package://arm_3001/meshes/Link0.stl" scale="0.05 0.05 0.05"/>
      </geometry>
      <material name="blue"/>
    </visual>
  </link>

  <joint name="link0tolink1" type="revolute">
    <origin xyz="-80 180 0" rpy="0 1.57 0"/>
    <parent link="link0"/>
    <child link="link1"/>
    <limit effort="1.0" lower="-2" upper="2" velocity="1.0"/>
    <axis xyz = "1 0 0"/>
  </joint>

  <link name="link1">
  <origin xyz="0 0 0 " rpy=" 0 0 0"/>
    <visual>
      <geometry>
      <mesh filename="package://arm_3001/meshes/Link1.stl" scale="0.05 0.05 0.05"/>
      </geometry>
      <material name="blue"/>
    </visual>
  </link>

  <joint name="link1tolink2" type="revolute">
    <origin xyz="0 0 220" rpy="0 0 0"/>
    <parent link="link1"/>
    <child link="link2"/>
    <limit effort="1.0" lower="-2" upper="2" velocity="1.0"/>
    <axis xyz = "1 0 0"/>
  </joint>

  <link name="link2">
  <origin xyz="0 0 0 " rpy=" 0 0 0"/>
    <visual>
      <geometry>
      <mesh filename="package://arm_3001/meshes/Link2.stl" scale="0.05 0.05 0.05"/>
      </geometry>
      <material name="blue"/>
    </visual>
  </link>


</robot>
